<?xml version="1.0" encoding="utf-8"?>
<!-- This URDF was automatically created by SolidWorks to URDF Exporter! Originally created by Stephen Brawner (brawner@gmail.com) 
     Commit Version: 1.5.1-0-g916b5db  Build Version: 1.5.7152.31018
     For more information, please see http://wiki.ros.org/sw_urdf_exporter -->
<robot
  name="jaka_kargo">
  <link name="world" />
  <link
    name="base_link">
    <inertial>
      <origin
        xyz="-0.004705 -0.00060963 0.13243"
        rpy="0 0 0" />
      <mass
        value="130.51" />
      <inertia
        ixx="4.5543"
        ixy="0.025771"
        ixz="-0.027935"
        iyy="7.3718"
        iyz="-0.027297"
        izz="10.465" />
    </inertial>
    <visual>
      <origin
        xyz="0 0 0"
        rpy="0 0 0" />
      <geometry>
        <mesh
          filename="package://jaka_kargo_description/meshes/jaka_kargo_meshes/base_link.STL" />
      </geometry>
      <material
        name="">
        <color
          rgba="0.79216 0.81961 0.93333 1" />
      </material>
    </visual>
    <collision>
      <origin
        xyz="0 0 0"
        rpy="0 0 0" />
      <geometry>
        <mesh
          filename="package://jaka_kargo_description/meshes/jaka_kargo_meshes/base_link.STL" />
      </geometry>
    </collision>
  </link>
  <joint 
    name="fixed" 
    type="fixed">
    <parent 
      link="world"/>
    <child 
      link="base_link"/>
  </joint>
  <link
    name="q_wheel_q_link">
    <inertial>
      <origin
        xyz="1.7653E-14 -2.0817E-16 -4.996E-16"
        rpy="0 0 0" />
      <mass
        value="0.79441" />
      <inertia
        ixx="0.0012498"
        ixy="-4.2665E-34"
        ixz="-2.562E-20"
        iyy="0.0012498"
        iyz="-1.3269E-20"
        izz="0.0022321" />
    </inertial>
    <visual>
      <origin
        xyz="0 0 0"
        rpy="0 0 0" />
      <geometry>
        <mesh
          filename="package://jaka_kargo_description/meshes/jaka_kargo_meshes/q_wheel_q_link.STL" />
      </geometry>
      <material
        name="">
        <color
          rgba="0.79216 0.81961 0.93333 1" />
      </material>
    </visual>
    <collision>
      <origin
        xyz="0 0 0"
        rpy="0 0 0" />
      <geometry>
        <mesh
          filename="package://jaka_kargo_description/meshes/jaka_kargo_meshes/q_wheel_q_link.STL" />
      </geometry>
    </collision>
  </link>
  <joint
    name="wheel_1"
    type="continuous">
    <origin
      xyz="0.29 0.1975 0.006"
      rpy="1.5708 0 3.1416" />
    <parent
      link="base_link" />
    <child
      link="q_wheel_q_link" />
    <axis
      xyz="0 0 -1" />
  </joint>
  <link
    name="h_wheel_q_link">
    <inertial>
      <origin
        xyz="4.9960036108132E-16 -1.66533453693773E-16 -0.0225000000000003"
        rpy="0 0 0" />
      <mass
        value="0.794411429544822" />
      <inertia
        ixx="0.0012498382871177"
        ixy="2.71050543121376E-20"
        ixz="-2.12299518338858E-18"
        iyy="0.0012498382871177"
        iyz="8.82909838013026E-19"
        izz="0.00223207369371143" />
    </inertial>
    <visual>
      <origin
        xyz="0 0 0"
        rpy="0 0 0" />
      <geometry>
        <mesh
          filename="package://jaka_kargo_description/meshes/jaka_kargo_meshes/h_wheel_q_link.STL" />
      </geometry>
      <material
        name="">
        <color
          rgba="0.792156862745098 0.819607843137255 0.933333333333333 1" />
      </material>
    </visual>
    <collision>
      <origin
        xyz="0 0 0"
        rpy="0 0 0" />
      <geometry>
        <mesh
          filename="package://jaka_kargo_description/meshes/jaka_kargo_meshes/h_wheel_q_link.STL" />
      </geometry>
    </collision>
  </link>
  <joint
    name="wheel_2"
    type="continuous">
    <origin
      xyz="-0.29 -0.175 0.006"
      rpy="1.5708 -0.44445 3.1416" />
    <parent
      link="base_link" />
    <child
      link="h_wheel_q_link" />
    <axis
      xyz="0 0 1" />
  </joint>
  <link
    name="q_wheel_x_link">
    <inertial>
      <origin
        xyz="-4.11923389842528E-09 -1.11694803406337E-09 0.103465509275845"
        rpy="0 0 0" />
      <mass
        value="0.785339554840708" />
      <inertia
        ixx="0.00308939784019361"
        ixy="5.17304098957238E-11"
        ixz="4.96196176433988E-11"
        iyy="0.00309418933601937"
        iyz="-1.24717430385355E-11"
        izz="0.000474989691670453" />
    </inertial>
    <visual>
      <origin
        xyz="0 0 0"
        rpy="0 0 0" />
      <geometry>
        <mesh
          filename="package://jaka_kargo_description/meshes/jaka_kargo_meshes/q_wheel_x_link.STL" />
      </geometry>
      <material
        name="">
        <color
          rgba="0.792156862745098 0.819607843137255 0.933333333333333 1" />
      </material>
    </visual>
    <collision>
      <origin
        xyz="0 0 0"
        rpy="0 0 0" />
      <geometry>
        <mesh
          filename="package://jaka_kargo_description/meshes/jaka_kargo_meshes/q_wheel_x_link.STL" />
      </geometry>
    </collision>
  </link>
  <joint
    name="wheel_3"
    type="revolute">
    <origin
      xyz="0.29 0.1975 0.145"
      rpy="3.1416 0 3.1416" />
    <parent
      link="base_link" />
    <child
      link="q_wheel_x_link" />
    <axis
      xyz="0 0 -1" />
    <limit
      lower="0"
      upper="0"
      effort="0"
      velocity="0" />
  </joint>
  <link
    name="h_wheel_x_link">
    <inertial>
      <origin
        xyz="4.11923400944758E-09 1.11694800630779E-09 0.103465509275845"
        rpy="0 0 0" />
      <mass
        value="0.785339554840708" />
      <inertia
        ixx="0.00308939784019361"
        ixy="5.1730409959755E-11"
        ixz="-4.96196176573177E-11"
        iyy="0.00309418933601937"
        iyz="1.24717428784332E-11"
        izz="0.000474989691670454" />
    </inertial>
    <visual>
      <origin
        xyz="0 0 0"
        rpy="0 0 0" />
      <geometry>
        <mesh
          filename="package://jaka_kargo_description/meshes/jaka_kargo_meshes/h_wheel_x_link.STL" />
      </geometry>
      <material
        name="">
        <color
          rgba="0.792156862745098 0.819607843137255 0.933333333333333 1" />
      </material>
    </visual>
    <collision>
      <origin
        xyz="0 0 0"
        rpy="0 0 0" />
      <geometry>
        <mesh
          filename="package://jaka_kargo_description/meshes/jaka_kargo_meshes/h_wheel_x_link.STL" />
      </geometry>
    </collision>
  </link>
  <joint
    name="wheel_4"
    type="revolute">
    <origin
      xyz="-0.29 -0.1975 0.145"
      rpy="3.1416 0 0" />
    <parent
      link="base_link" />
    <child
      link="h_wheel_x_link" />
    <axis
      xyz="0 0 -1" />
    <limit
      lower="0"
      upper="0"
      effort="0"
      velocity="0" />
  </joint>
  <link
    name="q_wheel_w_link">
    <inertial>
      <origin
        xyz="0 2.77555756156289E-17 -0.0522021955806991"
        rpy="0 0 0" />
      <mass
        value="0.399115828829937" />
      <inertia
        ixx="0.000479949648735608"
        ixy="1.528629771998E-20"
        ixz="6.93101240932377E-22"
        iyy="0.000479949648735608"
        iyz="2.52590988414871E-20"
        izz="0.000239885726427194" />
    </inertial>
    <visual>
      <origin
        xyz="0 0 0"
        rpy="0 0 0" />
      <geometry>
        <mesh
          filename="package://jaka_kargo_description/meshes/jaka_kargo_meshes/q_wheel_w_link.STL" />
      </geometry>
      <material
        name="">
        <color
          rgba="0.792156862745098 0.819607843137255 0.933333333333333 1" />
      </material>
    </visual>
    <collision>
      <origin
        xyz="0 0 0"
        rpy="0 0 0" />
      <geometry>
        <mesh
          filename="package://jaka_kargo_description/meshes/jaka_kargo_meshes/q_wheel_w_link.STL" />
      </geometry>
    </collision>
  </link>
  <joint
    name="wheel_5"
    type="continuous">
    <origin
      xyz="0.29 -0.1975 0.037"
      rpy="0 0 0" />
    <parent
      link="base_link" />
    <child
      link="q_wheel_w_link" />
    <axis
      xyz="0 0 1" />
  </joint>
  <link
    name="h_wheel_w_link">
    <inertial>
      <origin
        xyz="0 0 -0.052202195580699"
        rpy="0 0 0" />
      <mass
        value="0.399115828829937" />
      <inertia
        ixx="0.000479949648735608"
        ixy="1.528629771998E-20"
        ixz="6.93101240932378E-22"
        iyy="0.000479949648735608"
        iyz="2.52590988414871E-20"
        izz="0.000239885726427194" />
    </inertial>
    <visual>
      <origin
        xyz="0 0 0"
        rpy="0 0 0" />
      <geometry>
        <mesh
          filename="package://jaka_kargo_description/meshes/jaka_kargo_meshes/h_wheel_w_link.STL" />
      </geometry>
      <material
        name="">
        <color
          rgba="0.792156862745098 0.819607843137255 0.933333333333333 1" />
      </material>
    </visual>
    <collision>
      <origin
        xyz="0 0 0"
        rpy="0 0 0" />
      <geometry>
        <mesh
          filename="package://jaka_kargo_description/meshes/jaka_kargo_meshes/h_wheel_w_link.STL" />
      </geometry>
    </collision>
  </link>
  <joint
    name="wheel_6"
    type="continuous">
    <origin
      xyz="-0.29 0.1975 0.037"
      rpy="0 0 0" />
    <parent
      link="base_link" />
    <child
      link="h_wheel_w_link" />
    <axis
      xyz="0 0 1" />
  </joint>
  <link
    name="radar_r_link">
    <inertial>
      <origin
        xyz="5.55111512312578E-17 -8.32667268468867E-17 0.00850000000000012"
        rpy="0 0 0" />
      <mass
        value="0.0173915767921936" />
      <inertia
        ixx="2.42525060316059E-06"
        ixy="8.88640084284205E-37"
        ixz="9.08877628731946E-22"
        iyy="2.42525060316059E-06"
        iyz="-1.0515477229273E-21"
        izz="1.34975534043848E-06" />
    </inertial>
    <visual>
      <origin
        xyz="0 0 0"
        rpy="0 0 0" />
      <geometry>
        <mesh
          filename="package://jaka_kargo_description/meshes/jaka_kargo_meshes/radar_r_link.STL" />
      </geometry>
      <material
        name="">
        <color
          rgba="1 1 1 1" />
      </material>
    </visual>
    <collision>
      <origin
        xyz="0 0 0"
        rpy="0 0 0" />
      <geometry>
        <mesh
          filename="package://jaka_kargo_description/meshes/jaka_kargo_meshes/radar_r_link.STL" />
      </geometry>
    </collision>
  </link>
  <joint
    name="radar_1"
    type="fixed">
    <origin
      xyz="0.3262 -0.2262 0.217"
      rpy="0 0 0" />
    <parent
      link="base_link" />
    <child
      link="radar_r_link" />
    <axis
      xyz="0 0 0" />
  </joint>
  <link
    name="radar_l_link">
    <inertial>
      <origin
        xyz="0 8.32667268468867E-17 0.00850000000000006"
        rpy="0 0 0" />
      <mass
        value="0.0173915767921935" />
      <inertia
        ixx="2.42525060316058E-06"
        ixy="-1.05621993708082E-54"
        ixz="8.16351404007777E-38"
        iyy="2.42525060316058E-06"
        iyz="4.39072633523052E-39"
        izz="1.34975534043848E-06" />
    </inertial>
    <visual>
      <origin
        xyz="0 0 0"
        rpy="0 0 0" />
      <geometry>
        <mesh
          filename="package://jaka_kargo_description/meshes/jaka_kargo_meshes/radar_l_link.STL" />
      </geometry>
      <material
        name="">
        <color
          rgba="1 1 1 1" />
      </material>
    </visual>
    <collision>
      <origin
        xyz="0 0 0"
        rpy="0 0 0" />
      <geometry>
        <mesh
          filename="package://jaka_kargo_description/meshes/jaka_kargo_meshes/radar_l_link.STL" />
      </geometry>
    </collision>
  </link>
  <joint
    name="radar_2"
    type="fixed">
    <origin
      xyz="-0.3262 0.2262 0.217"
      rpy="0 0 0" />
    <parent
      link="base_link" />
    <child
      link="radar_l_link" />
    <axis
      xyz="0 0 0" />
  </joint>
  <link
    name="radar_3d_link">
    <inertial>
      <origin
        xyz="2.77555756156289E-17 -5.32282452371748E-20 0"
        rpy="0 0 0" />
      <mass
        value="0.00950816080674812" />
      <inertia
        ixx="9.34257820115813E-07"
        ixy="1.12011057891388E-40"
        ixz="-4.15564938231533E-23"
        iyy="9.34257820115813E-07"
        iyz="4.68650915267468E-40"
        izz="4.7102682213179E-07" />
    </inertial>
    <visual>
      <origin
        xyz="0 0 0"
        rpy="0 0 0" />
      <geometry>
        <mesh
          filename="package://jaka_kargo_description/meshes/jaka_kargo_meshes/radar_3d_link.STL" />
      </geometry>
      <material
        name="">
        <color
          rgba="1 1 1 1" />
      </material>
    </visual>
    <collision>
      <origin
        xyz="0 0 0"
        rpy="0 0 0" />
      <geometry>
        <mesh
          filename="package://jaka_kargo_description/meshes/jaka_kargo_meshes/radar_3d_link.STL" />
      </geometry>
    </collision>
  </link>
  <joint
    name="radar_3"
    type="fixed">
    <origin
      xyz="-0.13666 0 1.621"
      rpy="0 0 0" />
    <parent
      link="base_link" />
    <child
      link="radar_3d_link" />
    <axis
      xyz="0 0 0" />
  </joint>
  <link
    name="body_j1_link">
    <inertial>
      <origin
        xyz="0.13776 0.0009804 0.12266"
        rpy="0 0 0" />
      <mass
        value="14.555" />
      <inertia
        ixx="0.0746"
        ixy="0.0083689"
        ixz="-0.00037239"
        iyy="0.06535"
        iyz="0.0017525"
        izz="0.08194" />
    </inertial>
    <visual>
      <origin
        xyz="0 0 0"
        rpy="0 0 0" />
      <geometry>
        <mesh
          filename="package://jaka_kargo_description/meshes/jaka_kargo_meshes/body_j1_link.STL" />
      </geometry>
      <material
        name="">
        <color
          rgba="0.89804 0.91765 0.92941 1" />
      </material>
    </visual>
    <collision>
      <origin
        xyz="0 0 0"
        rpy="0 0 0" />
      <geometry>
        <mesh
          filename="package://jaka_kargo_description/meshes/jaka_kargo_meshes/body_j1_link.STL" />
      </geometry>
    </collision>
  </link>
  <joint
    name="body_j1"
    type="prismatic">
    <origin
      xyz="0.005341 0 0.309"
      rpy="0 0 0" />
    <parent
      link="base_link" />
    <child
      link="body_j1_link" />
    <axis
      xyz="0 0 1" />
    <limit
      lower="0"
      upper="0.8"
      effort="0"
      velocity="0" />
  </joint>
  <link
    name="body_j2_link">
    <inertial>
      <origin
        xyz="-0.0035627 0.17987 -0.00018158"
        rpy="0 0 0" />
      <mass
        value="11.807" />
      <inertia
        ixx="0.076003"
        ixy="-0.0037047"
        ixz="-8.1649E-06"
        iyy="0.046122"
        iyz="-5.9645E-06"
        izz="0.061501" />
    </inertial>
    <visual>
      <origin
        xyz="0 0 0"
        rpy="0 0 0" />
      <geometry>
        <mesh
          filename="package://jaka_kargo_description/meshes/jaka_kargo_meshes/body_j2_link.STL" />
      </geometry>
      <material
        name="">
        <color
          rgba="1 1 1 1" />
      </material>
    </visual>
    <collision>
      <origin
        xyz="0 0 0"
        rpy="0 0 0" />
      <geometry>
        <mesh
          filename="package://jaka_kargo_description/meshes/jaka_kargo_meshes/body_j2_link.STL" />
      </geometry>
    </collision>
  </link>
  <joint
    name="body_j2"
    type="revolute">
    <origin
      xyz="0.15 0 0.1175"
      rpy="1.5708 0 3.1416" />
    <parent
      link="body_j1_link" />
    <child
      link="body_j2_link" />
    <axis
      xyz="0 0 1" />
    <limit
      lower="0"
      upper="1.5707"
      effort="0"
      velocity="0" />
  </joint>
  <link
    name="camera_1_link">
    <inertial>
      <origin
        xyz="-2.63392011503605E-05 5.68892124452814E-05 0.013057264464305"
        rpy="0 0 0" />
      <mass
        value="0.089349902292875" />
      <inertia
        ixx="0.000108561501975541"
        ixy="-8.72098701788444E-08"
        ixz="-1.01367379383747E-08"
        iyy="1.08735008917201E-05"
        iyz="5.90127339915245E-08"
        izz="0.000109528628305252" />
    </inertial>
    <visual>
      <origin
        xyz="0 0 0"
        rpy="0 0 0" />
      <geometry>
        <mesh
          filename="package://jaka_kargo_description/meshes/jaka_kargo_meshes/camera_1_link.STL" />
      </geometry>
      <material
        name="">
        <color
          rgba="1 1 1 1" />
      </material>
    </visual>
    <collision>
      <origin
        xyz="0 0 0"
        rpy="0 0 0" />
      <geometry>
        <mesh
          filename="package://jaka_kargo_description/meshes/jaka_kargo_meshes/camera_1_link.STL" />
      </geometry>
    </collision>
  </link>
  <joint
    name="camera_1"
    type="fixed">
    <origin
      xyz="-0.061 0.119 -0.0002"
      rpy="1.5708 0 -1.5708" />
    <parent
      link="body_j2_link" />
    <child
      link="camera_1_link" />
    <axis
      xyz="0 0 0" />
  </joint>
  <link
    name="body_j3_link">
    <inertial>
      <origin
        xyz="4.9505E-05 0.00060124 0.050076"
        rpy="0 0 0" />
      <mass
        value="2.1924" />
      <inertia
        ixx="0.0083903"
        ixy="-2.3976E-05"
        ixz="-5.144E-06"
        iyy="0.0081117"
        iyz="-6.2244E-05"
        izz="0.0017213" />
    </inertial>
    <visual>
      <origin
        xyz="0 0 0"
        rpy="0 0 0" />
      <geometry>
        <mesh
          filename="package://jaka_kargo_description/meshes/jaka_kargo_meshes/body_j3_link.STL" />
      </geometry>
      <material
        name="">
        <color
          rgba="0.89804 0.91765 0.92941 1" />
      </material>
    </visual>
    <collision>
      <origin
        xyz="0 0 0"
        rpy="0 0 0" />
      <geometry>
        <mesh
          filename="package://jaka_kargo_description/meshes/jaka_kargo_meshes/body_j3_link.STL" />
      </geometry>
    </collision>
  </link>
  <joint
    name="body_j3"
    type="revolute">
    <origin
      xyz="0 0.3054 -0.0002"
      rpy="1.5708 0 3.1416" />
    <parent
      link="body_j2_link" />
    <child
      link="body_j3_link" />
    <axis
      xyz="0 0 1" />
    <limit
      lower="-1.5707"
      upper="1.5707"
      effort="0"
      velocity="0" />
  </joint>
  <link
    name="body_j4_link">
    <inertial>
      <origin
        xyz="-0.011051 0.032602 0.00026642"
        rpy="0 0 0" />
      <mass
        value="0.62325" />
      <inertia
        ixx="0.0026152"
        ixy="6.8094E-05"
        ixz="-2.7624E-06"
        iyy="0.0031794"
        iyz="4.117E-06"
        izz="0.001796" />
    </inertial>
    <visual>
      <origin
        xyz="0 0 0"
        rpy="0 0 0" />
      <geometry>
        <mesh
          filename="package://jaka_kargo_description/meshes/jaka_kargo_meshes/body_j4_link.STL" />
      </geometry>
      <material
        name="">
        <color
          rgba="0.79216 0.81961 0.93333 1" />
      </material>
    </visual>
    <collision>
      <origin
        xyz="0 0 0"
        rpy="0 0 0" />
      <geometry>
        <mesh
          filename="package://jaka_kargo_description/meshes/jaka_kargo_meshes/body_j4_link.STL" />
      </geometry>
    </collision>
  </link>
  <joint
    name="body_j4"
    type="revolute">
    <origin
      xyz="1.6524729565065E-05 0.000200000000069326 0.0949999999999905"
      rpy="1.5707963267949 0 3.05915625416187" />
    <parent
      link="body_j3_link" />
    <child
      link="body_j4_link" />
    <axis
      xyz="0 0 -1" />
    <limit
      lower="-0.3491"
      upper="0.7854"
      effort="0"
      velocity="0" />
  </joint>
  <link
    name="camera_2_link">
    <inertial>
      <origin
        xyz="-2.63392011491392E-05 5.68892124452915E-05 0.013057264464305"
        rpy="0 0 0" />
      <mass
        value="0.0893499022928749" />
      <inertia
        ixx="0.000108561501975541"
        ixy="-8.72098701788152E-08"
        ixz="-1.01367379383886E-08"
        iyy="1.08735008917201E-05"
        iyz="5.9012733991515E-08"
        izz="0.000109528628305252" />
    </inertial>
    <visual>
      <origin
        xyz="0 0 0"
        rpy="0 0 0" />
      <geometry>
        <mesh
          filename="package://jaka_kargo_description/meshes/jaka_kargo_meshes/camera_2_link.STL" />
      </geometry>
      <material
        name="">
        <color
          rgba="1 1 1 1" />
      </material>
    </visual>
    <collision>
      <origin
        xyz="0 0 0"
        rpy="0 0 0" />
      <geometry>
        <mesh
          filename="package://jaka_kargo_description/meshes/jaka_kargo_meshes/camera_2_link.STL" />
      </geometry>
    </collision>
  </link>
  <joint
    name="camera_2"
    type="fixed">
    <origin
      xyz="-0.034 0.053 -0.00020068"
      rpy="1.5708 0 -1.5708" />
    <parent
      link="body_j4_link" />
    <child
      link="camera_2_link" />
    <axis
      xyz="0 0 0" />
  </joint>
  <link
    name="arm_rj1_link">
    <inertial>
      <origin
        xyz="-3.4434E-07 1.8348E-06 0.15731"
        rpy="0 0 0" />
      <mass
        value="0.55666" />
      <inertia
        ixx="0.0011808"
        ixy="-1.2165E-08"
        ixz="-2.446E-08"
        iyy="0.0014386"
        iyz="-1.6681E-08"
        izz="0.00080021" />
    </inertial>
    <visual>
      <origin
        xyz="0 0 0"
        rpy="0 0 0" />
      <geometry>
        <mesh
          filename="package://jaka_kargo_description/meshes/jaka_kargo_meshes/arm_rj1_link.STL" />
      </geometry>
      <material
        name="">
        <color
          rgba="0.79216 0.81961 0.93333 1" />
      </material>
    </visual>
    <collision>
      <origin
        xyz="0 0 0"
        rpy="0 0 0" />
      <geometry>
        <mesh
          filename="package://jaka_kargo_description/meshes/jaka_kargo_meshes/arm_rj1_link.STL" />
      </geometry>
    </collision>
  </link>
  <joint
    name="arm_rj1"
    type="revolute">
    <origin
      xyz="-0.0047083 0.24 -0.0497"
      rpy="3.1416 -0.5236 -3.1416" />
    <parent
      link="body_j2_link" />
    <child
      link="arm_rj1_link" />
    <axis
      xyz="0 0 1" />
    <limit
      lower="-6.2832"
      upper="6.2832"
      effort="0"
      velocity="1.5708" />
  </joint>
  <link
    name="arm_rj2_link">
    <inertial>
      <origin
        xyz="1.4485E-05 -0.045302 -0.00076496"
        rpy="0 0 0" />
      <mass
        value="0.96181" />
      <inertia
        ixx="0.0035052"
        ixy="1.1957E-06"
        ixz="-5.6863E-09"
        iyy="0.0020948"
        iyz="3.3306E-05"
        izz="0.0026614" />
    </inertial>
    <visual>
      <origin
        xyz="0 0 0"
        rpy="0 0 0" />
      <geometry>
        <mesh
          filename="package://jaka_kargo_description/meshes/jaka_kargo_meshes/arm_rj2_link.STL" />
      </geometry>
      <material
        name="">
        <color
          rgba="0.79216 0.81961 0.93333 1" />
      </material>
    </visual>
    <collision>
      <origin
        xyz="0 0 0"
        rpy="0 0 0" />
      <geometry>
        <mesh
          filename="package://jaka_kargo_description/meshes/jaka_kargo_meshes/arm_rj2_link.STL" />
      </geometry>
    </collision>
  </link>
  <joint
    name="arm_rj2"
    type="revolute">
    <origin
      xyz="0 0 0.203"
      rpy="-1.5708 0 -3.1416" />
    <parent
      link="arm_rj1_link" />
    <child
      link="arm_rj2_link" />
    <axis
      xyz="0 0 1" />
    <limit
      lower="-1.8326"
      upper="1.8326"
      effort="0"
      velocity="1.5708" />
  </joint>
  <link
    name="arm_rj3_link">
    <inertial>
      <origin
        xyz="0.0064552 0.00044293 0.24018"
        rpy="0 0 0" />
      <mass
        value="1.3625" />
      <inertia
        ixx="0.0076963"
        ixy="3.7996E-07"
        ixz="-0.00011658"
        iyy="0.0077615"
        iyz="6.2992E-06"
        izz="0.0014739" />
    </inertial>
    <visual>
      <origin
        xyz="0 0 0"
        rpy="0 0 0" />
      <geometry>
        <mesh
          filename="package://jaka_kargo_description/meshes/jaka_kargo_meshes/arm_rj3_link.STL" />
      </geometry>
      <material
        name="">
        <color
          rgba="0.79216 0.81961 0.93333 1" />
      </material>
    </visual>
    <collision>
      <origin
        xyz="0 0 0"
        rpy="0 0 0" />
      <geometry>
        <mesh
          filename="package://jaka_kargo_description/meshes/jaka_kargo_meshes/arm_rj3_link.STL" />
      </geometry>
    </collision>
  </link>
  <joint
    name="arm_rj3"
    type="revolute">
    <origin
      xyz="0 0 0"
      rpy="1.5708 0 0" />
    <parent
      link="arm_rj2_link" />
    <child
      link="arm_rj3_link" />
    <axis
      xyz="0 0 1" />
    <limit
      lower="-6.2832"
      upper="6.2832"
      effort="0"
      velocity="2.0944" />
  </joint>
  <link
    name="arm_rj4_link">
    <inertial>
      <origin
        xyz="0.0046453 -0.031605 2.9125E-05"
        rpy="0 0 0" />
      <mass
        value="0.52447" />
      <inertia
        ixx="0.00135"
        ixy="5.7014E-05"
        ixz="6.5752E-08"
        iyy="0.00080283"
        iyz="2.8622E-06"
        izz="0.0010005" />
    </inertial>
    <visual>
      <origin
        xyz="0 0 0"
        rpy="0 0 0" />
      <geometry>
        <mesh
          filename="package://jaka_kargo_description/meshes/jaka_kargo_meshes/arm_rj4_link.STL" />
      </geometry>
      <material
        name="">
        <color
          rgba="0.79216 0.81961 0.93333 1" />
      </material>
    </visual>
    <collision>
      <origin
        xyz="0 0 0"
        rpy="0 0 0" />
      <geometry>
        <mesh
          filename="package://jaka_kargo_description/meshes/jaka_kargo_meshes/arm_rj4_link.STL" />
      </geometry>
    </collision>
  </link>
  <joint
    name="arm_rj4"
    type="revolute">
    <origin
      xyz="-0.00040027 0.0004006 0.3415"
      rpy="-1.5708 0 0" />
    <parent
      link="arm_rj3_link" />
    <child
      link="arm_rj4_link" />
    <axis
      xyz="0 0 1" />
    <limit
      lower="-2.531"
      upper="0.5236"
      effort="0"
      velocity="2.0944" />
  </joint>
  <link
    name="arm_rj5_link">
    <inertial>
      <origin
        xyz="-4.8561E-07 0.0037544 0.18203"
        rpy="0 0 0" />
      <mass
        value="0.79516" />
      <inertia
        ixx="0.0018569"
        ixy="-3.2662E-09"
        ixz="1.693E-08"
        iyy="0.0018879"
        iyz="-0.00013156"
        izz="0.00068253" />
    </inertial>
    <visual>
      <origin
        xyz="0 0 0"
        rpy="0 0 0" />
      <geometry>
        <mesh
          filename="package://jaka_kargo_description/meshes/jaka_kargo_meshes/arm_rj5_link.STL" />
      </geometry>
      <material
        name="">
        <color
          rgba="0.79216 0.81961 0.93333 1" />
      </material>
    </visual>
    <collision>
      <origin
        xyz="0 0 0"
        rpy="0 0 0" />
      <geometry>
        <mesh
          filename="package://jaka_kargo_description/meshes/jaka_kargo_meshes/arm_rj5_link.STL" />
      </geometry>
    </collision>
  </link>
  <joint
    name="arm_rj5"
    type="revolute">
    <origin
      xyz="0 0 0"
      rpy="1.5708 0 0" />
    <parent
      link="arm_rj4_link" />
    <child
      link="arm_rj5_link" />
    <axis
      xyz="0 0 1" />
    <limit
      lower="-6.2832"
      upper="6.2832"
      effort="0"
      velocity="2.618" />
  </joint>
  <link
    name="arm_rj6_link">
    <inertial>
      <origin
        xyz="1.1786E-08 -0.081599 0.0043018"
        rpy="0 0 0" />
      <mass
        value="0.57658" />
      <inertia
        ixx="0.0013509"
        ixy="2.557E-09"
        ixz="1.3038E-10"
        iyy="0.00051827"
        iyz="-0.00025524"
        izz="0.0012854" />
    </inertial>
    <visual>
      <origin
        xyz="0 0 0"
        rpy="0 0 0" />
      <geometry>
        <mesh
          filename="package://jaka_kargo_description/meshes/jaka_kargo_meshes/arm_rj6_link.STL" />
      </geometry>
      <material
        name="">
        <color
          rgba="0.79216 0.81961 0.93333 1" />
      </material>
    </visual>
    <collision>
      <origin
        xyz="0 0 0"
        rpy="0 0 0" />
      <geometry>
        <mesh
          filename="package://jaka_kargo_description/meshes/jaka_kargo_meshes/arm_rj6_link.STL" />
      </geometry>
    </collision>
  </link>
  <joint
    name="arm_rj6"
    type="revolute">
    <origin
      xyz="0 -0.00040035 0.23194"
      rpy="-1.5708 0 -3.1416" />
    <parent
      link="arm_rj5_link" />
    <child
      link="arm_rj6_link" />
    <axis
      xyz="0 0 1" />
    <limit
      lower="-1.8326"
      upper="1.8326"
      effort="0"
      velocity="2.618" />
  </joint>
  <link
    name="arm_rj7_link">
    <inertial>
      <origin
        xyz="1.2507E-09 -0.0017649 0.16661"
        rpy="0 0 0" />
      <mass
        value="0.23674" />
      <inertia
        ixx="0.00013702"
        ixy="-1.911E-20"
        ixz="-2.947E-18"
        iyy="0.00013721"
        iyz="1.592E-07"
        izz="0.00018988" />
    </inertial>
    <visual>
      <origin
        xyz="0 0 0"
        rpy="0 0 0" />
      <geometry>
        <mesh
          filename="package://jaka_kargo_description/meshes/jaka_kargo_meshes/arm_rj7_link.STL" />
      </geometry>
      <material
        name="">
        <color
          rgba="0.79216 0.81961 0.93333 1" />
      </material>
    </visual>
    <collision>
      <origin
        xyz="0 0 0"
        rpy="0 0 0" />
      <geometry>
        <mesh
          filename="package://jaka_kargo_description/meshes/jaka_kargo_meshes/arm_rj7_link.STL" />
      </geometry>
    </collision>
  </link>
  <joint
    name="arm_rj7"
    type="revolute">
    <origin
      xyz="0 0 0"
      rpy="1.5708 0 0" />
    <parent
      link="arm_rj6_link" />
    <child
      link="arm_rj7_link" />
    <axis
      xyz="0 0 1" />
    <limit
      lower="-6.2832"
      upper="6.2832"
      effort="0"
      velocity="2.618" />
  </joint>
  <link
    name="arm_lj1_link">
    <inertial>
      <origin
        xyz="3.44337481028578E-07 -1.83475565485036E-06 0.1573087968999"
        rpy="0 0 0" />
      <mass
        value="0.556662347813903" />
      <inertia
        ixx="0.0011808430638321"
        ixy="-1.21651482933721E-08"
        ixz="2.44596034165111E-08"
        iyy="0.00143862694636631"
        iyz="1.66813106492004E-08"
        izz="0.000800206575640912" />
    </inertial>
    <visual>
      <origin
        xyz="0 0 0"
        rpy="0 0 0" />
      <geometry>
        <mesh
          filename="package://jaka_kargo_description/meshes/jaka_kargo_meshes/arm_lj1_link.STL" />
      </geometry>
      <material
        name="">
        <color
          rgba="0.792156862745098 0.819607843137255 0.933333333333333 1" />
      </material>
    </visual>
    <collision>
      <origin
        xyz="0 0 0"
        rpy="0 0 0" />
      <geometry>
        <mesh
          filename="package://jaka_kargo_description/meshes/jaka_kargo_meshes/arm_lj1_link.STL" />
      </geometry>
    </collision>
  </link>
  <joint
    name="arm_lj1"
    type="revolute">
    <origin
      xyz="-0.0047083 0.24 0.0493"
      rpy="0 -0.5236 0" />
    <parent
      link="body_j2_link" />
    <child
      link="arm_lj1_link" />
    <axis
      xyz="0 0 1" />
    <limit
      lower="-6.2832"
      upper="6.2832"
      effort="0"
      velocity="1.5708" />
  </joint>
  <link
    name="arm_lj2_link">
    <inertial>
      <origin
        xyz="1.44853794678962E-05 -0.0453017722715205 -0.000764961094757766"
        rpy="0 0 0" />
      <mass
        value="0.961807814148841" />
      <inertia
        ixx="0.00350518754332591"
        ixy="1.19569254723563E-06"
        ixz="-5.6862634748206E-09"
        iyy="0.00209477715179098"
        iyz="3.33062563233202E-05"
        izz="0.00266142970050171" />
    </inertial>
    <visual>
      <origin
        xyz="0 0 0"
        rpy="0 0 0" />
      <geometry>
        <mesh
          filename="package://jaka_kargo_description/meshes/jaka_kargo_meshes/arm_lj2_link.STL" />
      </geometry>
      <material
        name="">
        <color
          rgba="0.792156862745098 0.819607843137255 0.933333333333333 1" />
      </material>
    </visual>
    <collision>
      <origin
        xyz="0 0 0"
        rpy="0 0 0" />
      <geometry>
        <mesh
          filename="package://jaka_kargo_description/meshes/jaka_kargo_meshes/arm_lj2_link.STL" />
      </geometry>
    </collision>
  </link>
  <joint
    name="arm_lj2"
    type="revolute">
    <origin
      xyz="0 0 0.203"
      rpy="-1.5708 0 0" />
    <parent
      link="arm_lj1_link" />
    <child
      link="arm_lj2_link" />
    <axis
      xyz="0 0 1" />
    <limit
      lower="-1.8326"
      upper="1.8326"
      effort="0"
      velocity="1.5708" />
  </joint>
  <link
    name="arm_lj3_link">
    <inertial>
      <origin
        xyz="0.0064552 0.00044293 0.24018"
        rpy="0 0 0" />
      <mass
        value="1.3625" />
      <inertia
        ixx="0.0076963"
        ixy="3.8E-07"
        ixz="-0.00011658"
        iyy="0.0077615"
        iyz="6.2992E-06"
        izz="0.0014739" />
    </inertial>
    <visual>
      <origin
        xyz="0 0 0"
        rpy="0 0 0" />
      <geometry>
        <mesh
          filename="package://jaka_kargo_description/meshes/jaka_kargo_meshes/arm_lj3_link.STL" />
      </geometry>
      <material
        name="">
        <color
          rgba="0.79216 0.81961 0.93333 1" />
      </material>
    </visual>
    <collision>
      <origin
        xyz="0 0 0"
        rpy="0 0 0" />
      <geometry>
        <mesh
          filename="package://jaka_kargo_description/meshes/jaka_kargo_meshes/arm_lj3_link.STL" />
      </geometry>
    </collision>
  </link>
  <joint
    name="arm_lj3"
    type="revolute">
    <origin
      xyz="0 0 0"
      rpy="1.5708 0 0" />
    <parent
      link="arm_lj2_link" />
    <child
      link="arm_lj3_link" />
    <axis
      xyz="0 0 1" />
    <limit
      lower="-6.2832"
      upper="6.2832"
      effort="0"
      velocity="2.0944" />
  </joint>
  <link
    name="arm_lj4_link">
    <inertial>
      <origin
        xyz="0.00464533566304387 -0.0316045382713815 2.91287642607552E-05"
        rpy="0 0 0" />
      <mass
        value="0.524473557771922" />
      <inertia
        ixx="0.00134996100278846"
        ixy="5.70136501603573E-05"
        ixz="6.56489294107197E-08"
        iyy="0.000802828356391943"
        iyz="2.86197563331402E-06"
        izz="0.00100052522805854" />
    </inertial>
    <visual>
      <origin
        xyz="0 0 0"
        rpy="0 0 0" />
      <geometry>
        <mesh
          filename="package://jaka_kargo_description/meshes/jaka_kargo_meshes/arm_lj4_link.STL" />
      </geometry>
      <material
        name="">
        <color
          rgba="0.792156862745098 0.819607843137255 0.933333333333333 1" />
      </material>
    </visual>
    <collision>
      <origin
        xyz="0 0 0"
        rpy="0 0 0" />
      <geometry>
        <mesh
          filename="package://jaka_kargo_description/meshes/jaka_kargo_meshes/arm_lj4_link.STL" />
      </geometry>
    </collision>
  </link>
  <joint
    name="arm_lj4"
    type="revolute">
    <origin
      xyz="-0.00040027 0.0004006 0.3415"
      rpy="-1.5708 0 0" />
    <parent
      link="arm_lj3_link" />
    <child
      link="arm_lj4_link" />
    <axis
      xyz="0 0 1" />
    <limit
      lower="-2.531"
      upper="0.5236"
      effort="0"
      velocity="2.0944" />
  </joint>
  <link
    name="arm_lj5_link">
    <inertial>
      <origin
        xyz="3.49144034128557E-07 -0.00455419831285453 0.182029909010219"
        rpy="0 0 0" />
      <mass
        value="0.79516120070511" />
      <inertia
        ixx="0.00185693827019273"
        ixy="-4.13411348678776E-09"
        ixz="-1.97268568256212E-08"
        iyy="0.00188793574277372"
        iyz="0.000131556172374901"
        izz="0.000682524955149531" />
    </inertial>
    <visual>
      <origin
        xyz="0 0 0"
        rpy="0 0 0" />
      <geometry>
        <mesh
          filename="package://jaka_kargo_description/meshes/jaka_kargo_meshes/arm_lj5_link.STL" />
      </geometry>
      <material
        name="">
        <color
          rgba="0.792156862745098 0.819607843137255 0.933333333333333 1" />
      </material>
    </visual>
    <collision>
      <origin
        xyz="0 0 0"
        rpy="0 0 0" />
      <geometry>
        <mesh
          filename="package://jaka_kargo_description/meshes/jaka_kargo_meshes/arm_lj5_link.STL" />
      </geometry>
    </collision>
  </link>
  <joint
    name="arm_lj5"
    type="revolute">
    <origin
      xyz="0 0 0"
      rpy="1.5708 0 0" />
    <parent
      link="arm_lj4_link" />
    <child
      link="arm_lj5_link" />
    <axis
      xyz="0 0 1" />
    <limit
      lower="-6.2832"
      upper="6.2832"
      effort="0"
      velocity="2.618" />
  </joint>
  <link
    name="arm_lj6_link">
    <inertial>
      <origin
        xyz="-1.73259996974484E-07 -0.081598959406494 0.00430187005546212"
        rpy="0 0 0" />
      <mass
        value="0.576577893328044" />
      <inertia
        ixx="0.00135089916745191"
        ixy="4.34054658717965E-09"
        ixz="2.91377497619271E-09"
        iyy="0.000518276366720639"
        iyz="-0.000255244068395691"
        izz="0.00128539468862911" />
    </inertial>
    <visual>
      <origin
        xyz="0 0 0"
        rpy="0 0 0" />
      <geometry>
        <mesh
          filename="package://jaka_kargo_description/meshes/jaka_kargo_meshes/arm_lj6_link.STL" />
      </geometry>
      <material
        name="">
        <color
          rgba="0.792156862745098 0.819607843137255 0.933333333333333 1" />
      </material>
    </visual>
    <collision>
      <origin
        xyz="0 0 0"
        rpy="0 0 0" />
      <geometry>
        <mesh
          filename="package://jaka_kargo_description/meshes/jaka_kargo_meshes/arm_lj6_link.STL" />
      </geometry>
    </collision>
  </link>
  <joint
    name="arm_lj6"
    type="revolute">
    <origin
      xyz="0 -0.00039946 0.23194"
      rpy="-1.5708 0 0" />
    <parent
      link="arm_lj5_link" />
    <child
      link="arm_lj6_link" />
    <axis
      xyz="0 0 1" />
    <limit
      lower="-1.8326"
      upper="1.8326"
      effort="0"
      velocity="2.618" />
  </joint>
  <link
    name="arm_lj7_link">
    <inertial>
      <origin
        xyz="1.25080362733954E-09 -0.0017016429966763 0.166613540986882"
        rpy="0 0 0" />
      <mass
        value="0.236737677400848" />
      <inertia
        ixx="0.000137023433905555"
        ixy="8.33831984783264E-21"
        ixz="3.38861198528252E-18"
        iyy="0.000137211005328673"
        iyz="-1.59201000792899E-07"
        izz="0.000189876557869699" />
    </inertial>
    <visual>
      <origin
        xyz="0 0 0"
        rpy="0 0 0" />
      <geometry>
        <mesh
          filename="package://jaka_kargo_description/meshes/jaka_kargo_meshes/arm_lj7_link.STL" />
      </geometry>
      <material
        name="">
        <color
          rgba="0.792156862745098 0.819607843137255 0.933333333333333 1" />
      </material>
    </visual>
    <collision>
      <origin
        xyz="0 0 0"
        rpy="0 0 0" />
      <geometry>
        <mesh
          filename="package://jaka_kargo_description/meshes/jaka_kargo_meshes/arm_lj7_link.STL" />
      </geometry>
    </collision>
  </link>
  <joint
    name="arm_lj7"
    type="revolute">
    <origin
      xyz="0 0 0"
      rpy="1.5708 0 0" />
    <parent
      link="arm_lj6_link" />
    <child
      link="arm_lj7_link" />
    <axis
      xyz="0 0 1" />
    <limit
      lower="-6.2832"
      upper="6.2832"
      effort="0"
      velocity="2.618" />
  </joint>
</robot>